Workbook

Sheet Etex Brand Identity
B2: Etex Brand Identity
B4: 🎨 Colour Palette
B5: Role | C5: Colour | D5: Hex
B6: Primary Brand | C6: Deep Charcoal / Near-Black | D6: #1A1A1A
B7: Accent / CTA | C7: Warm Orange | D7: #E8500A
B8: Navigation Underline | C8: Orange | D8: #E8500A
B9: Background | C9: Clean White | D9: #FFFFFF
B10: Body Text | C10: Medium Grey | D10: #4A4A4A
B11: Link / Subtext | C11: Muted Blue-Grey | D11: #6B7A8D
B12: Dark Banner | C12: Dark Slate | D12: #2D2D2D
B14: The palette is industrial and confident — almost monochromatic with a punchy orange used sparingly as the sole accent.
B18: 🔤 Typography
B19: Use | C19: Font | D19: Style
B20: Logo / Wordmark | C20: Custom geometric sans-serif | D20: Lowercase, tight tracking
B21: Headings | C21: Clean sans-serif (likely Roboto, Source Sans Pro, or a custom variant) | D21: Medium weight, dark
B22: Body / Navigation | C22: Neutral sans-serif | D22: Regular weight, spaced
B23: Tagline | C23: Same sans-serif | D23: Light/regular, sentence case
B25: The type system is functional and modern — no serifs, no decorative fonts. Everything serves clarity.
B29: 🏭 Brand Personality
B30: Industrial & professional — built for a manufacturing/construction audience
B31: Orange accent signals energy, safety (echoing hi-vis workwear), and action
B32: Restrained use of colour keeps it corporate and trustworthy
B33: The worker photography reinforces a people-first, hands-on brand voice

Sheet Dashboard
A1: ETEX AUSTRALIA | Altona Operations | Management Reporting Dashboard | CONFIDENTIAL | April 2025
A2: FY2025 Year-to-Date Performance · Period: January – April 2025 · Currency: AUD · AUD/EUR rate: 1.7523 avg / 1.7581 year-end [Source: Etex Financial Statements 2025 p.20]
A4: YTD Revenue | D4: YTD REBITDA | G4: REBITDA Margin | J4: CapEx Spent | M4: Headcount
A5: $AUD 000s | D5: $AUD 000s | G5: % | J5: $AUD 000s | M5: FTE
A6: Actual: 158,240 | D6: Actual: 29,220 | G6: Actual: 18.5% | J6: Actual: 8,450 | M6: Actual: 312
A7: Budget: 161,800 | D7: Budget: 32,200 | G7: Budget: 19.9% | J7: Budget: 9,800 | M7: Budget: 318
A8: Achievement: 97.8% | D8: Achievement: 90.7% | G8: Achievement: n/a | J8: Achievement: 86.2% | M8: Achievement: 98.1%
A10: Etex Group | 5-Year Financial Performance | J10: Etex Australia | Strategic Context
A11: Metric | B11: 2021 | C11: 2022 | D11: 2023 | E11: 2024 | F11: 2025 | G11: YoY Chg | H11: Note | J11: Geography share of Group | L11: 8.2% of EUR 3,747M revenue
A12: Revenue (EUR M) | B12: 2972 | C12: 3714 | D12: 3808 | E12: 3777 | F12: 3747 | G12: =F12-E12 -> -30 | H12: Source: Etex 2025 Annual Report, p.10 | J12: AUD Annual Revenue (est.) | L12: ~AUD 538.5M (@ 1.7523 AUD/EUR · source: Etex FS 2025 p.20)
A13: REBITDA (EUR M) | B13: 570 | C13: 645 | D13: 712 | E13: 695 | F13: 698 | G13: =F13-E13 -> 3 | H13: Source: Etex 2025 Annual Report, p.10 | J13: Monthly run-rate | L13: ~AUD 44.9M per month (FY25 annualised)
A14: REBITDA Margin % | B14: 0.192 | C14: 17.4% | D14: 18.7% | E14: 18.4% | F14: 18.6% | G14: n/a | H14: Record 5yr avg: 18.7% | J14: Key division | L14: Building Performance — plasterboard, fibre cement, fire protection
A15: Net Recurring Profit | B15: 278 | C15: 285 | D15: 272 | E15: 264 | F15: 269 | G15: =F15-E15 -> 5 | H15: Source: Etex 2025 Annual Report, p.10 | J15: BGC Acquisition | L15: BGC synergies confirmed driver of Australia REBITDA improvement in FY2025 (Directors' Report p.5)
A16: CapEx (EUR M) | B16: 199 | C16: 302 | D16: 371 | E16: 264 | F16: 299 | G16: =F16-E16 -> 35 | H16: Includes Bristol plant (largest ever) | J16: Market conditions | L16: Sales growth confirmed: Australia named as one of top growth markets in 2025 (DR p.5)
A17: Net Debt (EUR M) | B17: 214 | C17: 1031 | D17: 1039 | E17: 1109 | F17: 1027 | G17: =F17-E17 -> -82 | H17: -7.4% YoY debt reduction | J17: Group cost reduction | L17: EUR 57M group mfg cost reduction; energy intensity -2.5% avg across all technologies
A18: Employees (FTE) | B18: 12214 | C18: 13712 | D18: 13553 | E18: 13432 | F18: 13037 | G18: =F18-E18 -> -395 | H18: Altona ~312 FTE | J18: Key strategic programme | L18: SHAPE: EUR 91M savings in Building Performance; Bristol plant inaugurated
J19: Sustainability target | L19: GHG intensity -7.75% vs 2024; SBTi targets submitted for validation; EcoVadis Silver
A21: Legend: | B21: GREEN | D21: ≥ 98% of Budget | E21: AMBER | G21: 90–97% of Budget | H21: RED | J21: < 90% of Budget

Sheet Group P&L
A1: ETEX AUSTRALIA | Etex Group | Consolidated Income Statement | IFRS | EUR 000s | CONFIDENTIAL | April 2025
A2: Source: Etex NV Directors' Report & Financial Statements 2025 · Audited by PwC · IFRS · All amounts EUR thousands
B3: Notes | C3: FY2024 (EUR 000s) | D3: FY2025 (EUR 000s) | E3: Change EUR 000s | F3: Change % | G3: 2025 % Revenue | H3: Commentary
A4: Revenue | B4: (1) | C4: 3777041 | D4: 3746880 | E4: =D4-C4 -> -30161 | F4: =IFERROR(E4/ABS(C4),"-") -> -0.0079853515 | G4: =IFERROR(D4/D4,"-") -> 1 | H4: Directors' Report p.5; AR p.10
A5: Cost of sales | B5: (3) | C5: -2629701 | D5: -2584181 | E5: =D5-C5 -> 45520 | F5: =IFERROR(E5/ABS(C5),"-") -> 0.017309953 | G5: =IFERROR(D5/D4,"-") -> -0.68968875 | H5: Financial Statements p.12; incl. mfg, materials, labour
A6: GROSS PROFIT | C6: 1147340 | D6: 1162699 | E6: =D6-C6 -> 15359 | F6: =IFERROR(E6/ABS(C6),"-") -> 0.013386616 | G6: =IFERROR(D6/D4,"-") -> 0.31031125 | H6: 31.0% of revenue in 2025 vs 30.4% in 2024
A8: Distribution expenses | B8: (3) | C8: -489795 | D8: -488567 | E8: =D8-C8 -> 1228 | F8: =IFERROR(E8/ABS(C8),"-") -> 0.0025071714 | G8: =IFERROR(D8/D4,"-") -> -0.13039302 | H8: Stable YoY; 13.0% of revenue
A9: Administrative and general expenses | B9: (3) | C9: -206987 | D9: -217537 | E9: =D9-C9 -> -10550 | F9: =IFERROR(E9/ABS(C9),"-") -> -0.050969385 | G9: =IFERROR(D9/D4,"-") -> -0.058058171 | H9: Up 5.1%; overhead ratio 5.8% of revenue
A10: Other operating charges & income | B10: (4) | C10: -28770 | D10: -31305 | E10: =D10-C10 -> -2535 | F10: =IFERROR(E10/ABS(C10),"-") -> -0.088112617 | G10: =IFERROR(D10/D4,"-") -> -0.0083549513 | H10: Carbon credits, other operating items
A11: OPERATING INCOME BEFORE NON-RECURRING (REBIT) | C11: 421787 | D11: 425291 | E11: =D11-C11 -> 3504 | F11: =IFERROR(E11/ABS(C11),"-") -> 0.0083075107 | G11: =IFERROR(D11/D4,"-") -> 0.11350537 | H11: 11.4% margin (2024: 11.2%); near-record
A13: Gain/(loss) on disposal of assets | B13: (5) | C13: 1655 | D13: 4287 | E13: =D13-C13 -> 2632 | F13: =IFERROR(E13/ABS(C13),"-") -> 1.5903323 | G13: =IFERROR(D13/D4,"-") -> 0.0011441519 | H13: Gains on disposal of non-operating properties
A14: Other non-recurring items | B14: (5) | C14: -89806 | D14: -62776 | E14: =D14-C14 -> 27030 | F14: =IFERROR(E14/ABS(C14),"-") -> 0.30098212 | G14: =IFERROR(D14/D4,"-") -> -0.016754206 | H14: Restructuring, M&A costs, asbestos removal
A15: OPERATING INCOME (EBIT) | C15: 333637 | D15: 366802 | E15: =D15-C15 -> 33165 | F15: =IFERROR(E15/ABS(C15),"-") -> 0.099404443 | G15: =IFERROR(D15/D4,"-") -> 0.097895316 | H15: +9.9% YoY; 9.8% margin (2024: 8.8%)
A17: Interest income | B17: (6) | C17: 25932 | D17: 21676 | E17: =D17-C17 -> -4256 | F17: =IFERROR(E17/ABS(C17),"-") -> -0.16412155 | G17: =IFERROR(D17/D4,"-") -> 0.0057850799
A18: Interest expenses | B18: (6) | C18: -81194 | D18: -71925 | E18: =D18-C18 -> 9269 | F18: =IFERROR(E18/ABS(C18),"-") -> 0.11415868 | G18: =IFERROR(D18/D4,"-") -> -0.019195971 | H18: Lower debt + lower reference rates in 2025
A19: Other financial income | B19: (6) | C19: 46878 | D19: 31700 | E19: =D19-C19 -> -15178 | F19: =IFERROR(E19/ABS(C19),"-") -> -0.32377661 | G19: =IFERROR(D19/D4,"-") -> 0.0084603724 | H19: Incl. USD-linked bond gains in Argentina
A20: Other financial expense | B20: (6) | C20: -78543 | D20: -31166 | E20: =D20-C20 -> 47377 | F20: =IFERROR(E20/ABS(C20),"-") -> 0.60319825 | G20: =IFERROR(D20/D4,"-") -> -0.0083178538 | H20: 2024 high driven by Argentina hyperinflation
A21: Share of profit — equity accounted investees | B21: (13) | C21: 866 | D21: 2084 | E21: =D21-C21 -> 1218 | F21: =IFERROR(E21/ABS(C21),"-") -> 1.4064665 | G21: =IFERROR(D21/D4,"-") -> 0.00055619609
A22: NET FINANCIAL CHARGES (net) | C22: -86061 | D22: -50297 | E22: =D22-C22 -> 35764 | F22: =IFERROR(E22/ABS(C22),"-") -> 0.4155657 | G22: =IFERROR(D22/D4,"-") -> -0.013423702 | H22: Improved significantly: -€50M vs -€87M in 2024
A24: PROFIT BEFORE INCOME TAX | C24: 247576 | D24: 319171 | E24: =D24-C24 -> 71595 | F24: =IFERROR(E24/ABS(C24),"-") -> 0.28918393 | G24: =IFERROR(D24/D4,"-") -> 0.085183139 | H24: +28.9% YoY
A25: Income tax expense | B25: (7) | C25: -80380 | D25: -82021 | E25: =D25-C25 -> -1641 | F25: =IFERROR(E25/ABS(C25),"-") -> -0.020415526 | G25: =IFERROR(D25/D4,"-") -> -0.02189048 | H25: Effective tax rate 25.9% (2024: 32.6%)
A26: PROFIT FOR THE YEAR | C26: 167196 | D26: 237150 | E26: =D26-C26 -> 69954 | F26: =IFERROR(E26/ABS(C26),"-") -> 0.41839518 | G26: =IFERROR(D26/D4,"-") -> 0.063292659 | H26: +42.0% YoY
A27: Attributable to shareholders of Etex | C27: 165791 | D27: 237156 | E27: =D27-C27 -> 71365 | F27: =IFERROR(E27/ABS(C27),"-") -> 0.43045159 | G27: =IFERROR(D27/D4,"-") -> 0.063294261 | H27: EPS: €3.03 (2024: €2.12)
A28: Attributable to non-controlling interests | C28: 1406 | D28: -6 | E28: =D28-C28 -> -1412 | F28: =IFERROR(E28/ABS(C28),"-") -> -1.0042674 | G28: =IFERROR(D28/D4,"-") -> -1.6013323e-06
A30: NET RECURRING PROFIT (Group share) | C30: 264000 | D30: 269000 | E30: =D30-C30 -> 5000 | F30: =IFERROR(E30/ABS(C30),"-") -> 0.018939394 | G30: =IFERROR(D30/D4,"-") -> 0.071793065 | H30: +1.8% YoY; non-IFRS measure defined by Etex since 2007
A31: REBITDA | C31: 695110 | D31: 697923 | E31: =D31-C31 -> 2813 | F31: =IFERROR(E31/ABS(C31),"-") -> 0.0040468415 | G31: =IFERROR(D31/D4,"-") -> 0.18626777 | H31: 18.6% of revenue (2024: 18.4%); second-best in history
A32: Capital expenditure | B32: (27) | C32: -220039 | D32: -250245 | E32: =D32-C32 -> -30206 | F32: =IFERROR(E32/ABS(C32),"-") -> -0.13727566 | G32: =IFERROR(D32/D4,"-") -> -0.066787567 | H32: Owned assets only; +13.6% YoY incl. Bristol plant
A33: Free cash flow from operations | C33: 429275 | D33: 518299 | E33: =D33-C33 -> 89024 | F33: =IFERROR(E33/ABS(C33),"-") -> 0.20738221 | G33: =IFERROR(D33/D4,"-") -> 0.13832816 | H33: +20.7% YoY; strong cash conversion

Sheet Group Balance Sheet
A1: ETEX AUSTRALIA | Etex Group | Consolidated Balance Sheet & Cash Flow | IFRS | EUR 000s | CONFIDENTIAL | April 2025
A2: Source: Etex NV Financial Statements 2025 (Audited PwC) · IFRS · EUR thousands · AUD/EUR year-end rate: 1.7581 · Average rate FY2025: 1.7523
B3: Notes | C3: 31-Dec-2024 (EUR 000s) | D3: 31-Dec-2025 (EUR 000s) | E3: Change EUR 000s | F3: Change % | G3: Commentary
A4: NON-CURRENT ASSETS | C4: 3658430 | D4: 3592949 | E4: =D4-C4 -> -65481 | F4: =IFERROR(E4/ABS(C4),"-") -> -0.017898661
A5: Property, plant & equipment | B5: (8) | C5: 2234123 | D5: 2209336 | E5: =D5-C5 -> -24787 | F5: =IFERROR(E5/ABS(C5),"-") -> -0.011094734 | G5: Incl. leased assets €185.8M. Net of FX translation.
A6: Goodwill | B6: (9) | C6: 753850 | D6: 751799 | E6: =D6-C6 -> -2051 | F6: =IFERROR(E6/ABS(C6),"-") -> -0.0027207004 | G6: BGC and other acquisitions. FX impact offset Drumarkon addition.
A7: Other intangible assets | B7: (10) | C7: 452282 | D7: 418288 | E7: =D7-C7 -> -33994 | F7: =IFERROR(E7/ABS(C7),"-") -> -0.075161072 | G7: Software, brands, tech, customer lists from acquisitions
A8: Deferred tax assets | B8: (25) | C8: 96138 | D8: 94307 | E8: =D8-C8 -> -1831 | F8: =IFERROR(E8/ABS(C8),"-") -> -0.019045539
A9: Employee benefits assets | B9: (22) | C9: 71177 | D9: 78208 | E9: =D9-C9 -> 7031 | F9: =IFERROR(E9/ABS(C9),"-") -> 0.09878191 | G9: Pension surplus positions
A10: Other non-current assets | C10: 50860 | D10: 40147 | E10: =D10-C10 -> -10713 | F10: =IFERROR(E10/ABS(C10),"-") -> -0.21063704 | G10: Investment properties, equity investees, other
A12: CURRENT ASSETS | C12: 1363167 | D12: 1443975 | E12: =D12-C12 -> 80808 | F12: =IFERROR(E12/ABS(C12),"-") -> 0.059279604
A13: Inventories | B13: (16) | C13: 503022 | D13: 509842 | E13: =D13-C13 -> 6820 | F13: =IFERROR(E13/ABS(C13),"-") -> 0.013558055 | G13: Trade working capital: 9.0% of sales (2024: 8.0%)
A14: Trade and other receivables | B14: (15) | C14: 442854 | D14: 449798 | E14: =D14-C14 -> 6944 | F14: =IFERROR(E14/ABS(C14),"-") -> 0.015680111
A15: Other current assets | B15: (15) | C15: 88061 | D15: 72611 | E15: =D15-C15 -> -15450 | F15: =IFERROR(E15/ABS(C15),"-") -> -0.17544657
A16: Cash and cash equivalents | B16: (18) | C16: 329230 | D16: 411724 | E16: =D16-C16 -> 82494 | F16: =IFERROR(E16/ABS(C16),"-") -> 0.25056647 | G16: +24.9% YoY; strong operating cash generation
A18: TOTAL ASSETS | C18: 5021597 | D18: 5036924 | E18: =D18-C18 -> 15327 | F18: =IFERROR(E18/ABS(C18),"-") -> 0.0030522163
A20: TOTAL EQUITY | B20: (19) | C20: 2030500 | D20: 2093002 | E20: =D20-C20 -> 62502 | F20: =IFERROR(E20/ABS(C20),"-") -> 0.030781581 | G20: Equity ratio: 41.6% (2024: 40.4%)
A21: Attributable to Etex shareholders | C21: 2006012 | D21: 2070556 | E21: =D21-C21 -> 64544 | F21: =IFERROR(E21/ABS(C21),"-") -> 0.032175281
A22: Non-controlling interests | C22: 24488 | D22: 22446 | E22: =D22-C22 -> -2042 | F22: =IFERROR(E22/ABS(C22),"-") -> -0.083387782
A24: NON-CURRENT LIABILITIES | C24: 1763014 | D24: 1782253 | E24: =D24-C24 -> 19239 | F24: =IFERROR(E24/ABS(C24),"-") -> 0.010912562
A25: Provisions (non-current) | B25: (20) | C25: 103601 | D25: 99200 | E25: =D25-C25 -> -4401 | F25: =IFERROR(E25/ABS(C25),"-") -> -0.042480285 | G25: Asbestos provisions, restructuring, decommissioning
A26: Employee benefits liabilities | B26: (22) | C26: 130122 | D26: 117672 | E26: =D26-C26 -> -12450 | F26: =IFERROR(E26/ABS(C26),"-") -> -0.095679439 | G26: Pension obligations
A27: Loans and borrowings | B27: (24) | C27: 1308480 | D27: 1353471 | E27: =D27-C27 -> 44991 | F27: =IFERROR(E27/ABS(C27),"-") -> 0.034384171 | G27: Incl. leasing €156.2M
A28: Deferred tax liabilities | B28: (25) | C28: 206274 | D28: 188536 | E28: =D28-C28 -> -17738 | F28: =IFERROR(E28/ABS(C28),"-") -> -0.085992418
A29: Other non-current liabilities | B29: (26) | C29: 14537 | D29: 23374 | E29: =D29-C29 -> 8837 | F29: =IFERROR(E29/ABS(C29),"-") -> 0.60789709
A31: CURRENT LIABILITIES | C31: 1228083 | D31: 1161669 | E31: =D31-C31 -> -66414 | F31: =IFERROR(E31/ABS(C31),"-") -> -0.054079407
A32: Provisions (current) | B32: (20) | C32: 75088 | D32: 52753 | E32: =D32-C32 -> -22335 | F32: =IFERROR(E32/ABS(C32),"-") -> -0.29745099 | G32: Reduced restructuring provisions
A33: Current loans and borrowings | B33: (24) | C33: 217714 | D33: 157407 | E33: =D33-C33 -> -60307 | F33: =IFERROR(E33/ABS(C33),"-") -> -0.27700102 | G33: Significant reduction — debt management
A34: Trade and other liabilities | B34: (26) | C34: 935281 | D34: 951509 | E34: =D34-C34 -> 16228 | F34: =IFERROR(E34/ABS(C34),"-") -> 0.017350935
A36: TOTAL EQUITY AND LIABILITIES | C36: 5021597 | D36: 5036924 | E36: =D36-C36 -> 15327 | F36: =IFERROR(E36/ABS(C36),"-") -> 0.0030522163 | G36: Check: must equal Total Assets
A38: NET FINANCIAL DEBT | C38: 1109000 | D38: 1027000 | E38: =D38-C38 -> -82000 | F38: =IFERROR(E38/ABS(C38),"-") -> -0.073940487 | G38: -7.4% YoY; excl. factoring €214M: €1,241M
A41: CONSOLIDATED STATEMENT OF CASH FLOWS (EUR 000s)
B42: Notes | C42: FY2024 | D42: FY2025 | E42: Change | F42: Change %
A43: Operating income (EBIT) | B43: (27) | C43: 333637 | D43: 366802 | E43: =D43-C43 -> 33165 | F43: =IFERROR(E43/ABS(C43),"-") -> 0.099404443
A44: Depreciation, amortisation & impairment | B44: (27) | C44: 285038 | D44: 287627 | E44: =D44-C44 -> 2589 | F44: =IFERROR(E44/ABS(C44),"-") -> 0.0090829995
A45: Other non-cash / working capital movements | B45: (27) | C45: -189400 | D45: -136130 | E45: =D45-C45 -> 53270 | F45: =IFERROR(E45/ABS(C45),"-") -> 0.2812566
A46: CASH FLOW FROM OPERATING ACTIVITIES | C46: 429275 | D46: 518299 | E46: =D46-C46 -> 89024 | F46: =IFERROR(E46/ABS(C46),"-") -> 0.20738221
A48: Capital expenditure — owned assets | B48: (27) | C48: -220039 | D48: -250245 | E48: =D48-C48 -> -30206 | F48: =IFERROR(E48/ABS(C48),"-") -> -0.13727566
A49: Acquisitions (net) | B49: (9) | C49: -101599 | D49: -5668 | E49: =D49-C49 -> 95931 | F49: =IFERROR(E49/ABS(C49),"-") -> 0.94421205
A50: Other investing activities | C50: -10945 | D50: 8217 | E50: =D50-C50 -> 19162 | F50: =IFERROR(E50/ABS(C50),"-") -> 1.7507538
...

Sheet BGC Synergy Tracker
A1: ETEX AUSTRALIA | BGC Acquisition | Australia Synergy Tracker | AUD $000s | CONFIDENTIAL | April 2025
A2: BGC acquisition confirmed as explicit driver of Australia REBITDA improvement in FY2025. Source: Etex Directors' Report 2025 p.5 — 'REBITDA improvements … in Australia due to synergies realised with acquired BGC business.' AUD/EUR avg rate: 1.7523
A4: SECTION A — BGC Integration Synergy Categories & FY2025 Delivery
A5: Synergy Category | B5: Synergy Type | C5: FY25 Target AUD $000s | D5: FY25 Actual AUD $000s | E5: Delivery % | F5: FY26 Full-Run AUD $000s | G5: Cumulative AUD $000s | H5: Status | I5: Key Driver | J5: Risk | K5: Action Owner
A6: Manufacturing overhead | B6: Cost | C6: 4800 | D6: 5100 | E6: =IFERROR(D6/C6,"-") -> 1.0625 | F6: 7200 | G6: =D6 -> 5100 | H6: ON TRACK | I6: Plant consolidation Altona+BGC; shared kiln scheduling | J6: Low | K6: Manufacturing Mgr
A7: Procurement & materials | B7: Cost | C7: 3200 | D7: 2800 | E7: =IFERROR(D7/C7,"-") -> 0.875 | F7: 4800 | G7: =D7 -> 2800 | H7: BEHIND | I7: Gypsum volume rebate; combined paper liner contract | J7: Medium | K7: Procurement Lead
A8: Logistics & distribution | B8: Cost | C8: 2400 | D8: 2650 | E8: =IFERROR(D8/C8,"-") -> 1.1041667 | F8: 3600 | G8: =D8 -> 2650 | H8: ON TRACK | I8: Route optimisation WA↔VIC; shared distribution network | J8: Low | K8: Supply Chain Ops
A9: Shared services & admin | B9: Cost | C9: 1800 | D9: 1600 | E9: =IFERROR(D9/C9,"-") -> 0.88888889 | F9: 2800 | G9: =D9 -> 1600 | H9: BEHIND | I9: Finance, HR, IT consolidation under Etex platforms | J9: Low | K9: CFO / HR
A10: Revenue — channel access | B10: Revenue | C10: 3500 | D10: 2900 | E10: =IFERROR(D10/C10,"-") -> 0.82857143 | F10: 5500 | G10: =D10 -> 2900 | H10: BEHIND | I10: BGC builder relationships → Siniat brand uplift; cross-sell | J10: High | K10: Sales Director
A11: Revenue — premium mix | B11: Revenue | C11: 2200 | D11: 2680 | E11: =IFERROR(D11/C11,"-") -> 1.2181818 | F11: 3800 | G11: =D11 -> 2680 | H11: ON TRACK | I11: BGC customers migrate to Siniat Premium & Moisture+ | J11: Medium | K11: Sales Director
A12: Working capital release | B12: WC | C12: 2000 | D12: 1850 | E12: =IFERROR(D12/C12,"-") -> 0.925 | F12: 2200 | G12: =D12 -> 1850 | H12: BEHIND | I12: Inventory rationalisation; supplier terms aligned | J12: Medium | K12: Finance Manager
A13: TOTAL SYNERGIES | C13: =SUM(C6:C12) -> 19900 | D13: =SUM(D6:D12) -> 19580 | E13: =IFERROR(D13/C13,"-") -> 0.9839196 | F13: =SUM(F6:F12) -> 29900 | G13: =SUM(G6:G12) -> 19580
A15: SECTION B — REBITDA Bridge | Pre-BGC → Post-BGC Integration (AUD $000s)
A16: Step | B16: Description | C16: AUD $000s | D16: Cumulative $000s | E16: % of Revenue | F16: Source / Note
A17: 1 | B17: FY2024 REBITDA — Etex Australia pre-BGC full effect | C17: 91000 | D17: 91000 | E17: 17.8% | F17: Est. AUD 511M rev × 17.8%; FY24 AU rev ~AUD 511M (€311.7M × 1.6399)
A18: 2 | B18: Volume recovery — new channel via BGC | C18: 2900 | D18: =D17+C18 -> 93900 | F18: BGC revenue synergy: builder relationships → Siniat channel
A19: 3 | B19: Manufacturing cost savings — overhead consolidation | C19: 5100 | D19: =D18+C19 -> 99000 | F19: Plant optimisation; shared scheduling
A20: 4 | B20: Procurement savings — materials & logistics | C20: 5450 | D20: =D19+C20 -> 104450 | F20: Combined gypsum rebate + logistics + shared services
A21: 5 | B21: Premium mix improvement — Siniat brand uplift | C21: 2680 | D21: =D20+C21 -> 107130 | F21: ASP improvement; premium % rising in BGC customer base
A22: 6 | B22: FX headwind (AUD/EUR weakening vs 2024) | C22: -4200 | D22: =D21+C22 -> 102930 | F22: AUD avg 1.7523 vs 1.6399 in 2024: ~8% AUD weaker → reduces EUR-translated profit
A23: 7 | B23: Other — working capital, one-off integration costs | C23: -2730 | D23: =D22+C23 -> 100200 | F23: M&A integration costs, transition services; normalises in FY26
A24: FY25 | B24: FY2025 REBITDA — Etex Australia (est.) | C24: =SUM(C17:C23) -> 100200 | D24: =C24 -> 100200 | E24: 18.6% | F24: Consistent with group REBITDA margin 18.6%; BGC synergies key driver
A27: SECTION C — Integration Milestones & Remaining Actions
A28: Milestone | B28: Owner | C28: Target Date | D28: Status | E28: Value AUD $000s | F28: Notes
A29: ERP system migration — BGC entities to SAP | B29: IT / Finance | C29: Jun-25 | D29: IN PROGRESS | E29: - | F29: Go-live delayed 6wks; parallel run ongoing
A30: Gypsum procurement contract renegotiation | B30: Procurement | C30: Mar-25 | D30: COMPLETE | E30: 2800 | F30: Combined volume rebate locked until Dec-26
A31: Logistics network consolidation | B31: Supply Chain | C31: Apr-25 | D31: COMPLETE | E31: 2650 | F31: 3PL contract renegotiated; 2 depots merged
A32: Brand transition — BGC SKUs to Siniat labels | B32: Marketing | C32: Sep-25 | D32: PLANNED | E32: - | F32: Label changeover program commencing Q3
A33: Customer segmentation — BGC builder accounts | B33: Sales | C33: Jun-25 | D33: IN PROGRESS | E33: 2900 | F33: SHINE programme rollout to BGC accounts
A34: Finance reporting consolidation | B34: Finance Manager | C34: Apr-25 | D34: COMPLETE | E34: 1600 | F34: BGC entities reporting on Etex monthly pack
A35: Headcount restructure completion | B35: People / CFO | C35: Jun-25 | D35: IN PROGRESS | E35: 3200 | F35: Voluntary redundancy program; 18 FTE reduction
A36: Full synergy run-rate achievement | B36: CFO / CEO | C36: Dec-25 | D36: PLANNED | E36: 29900 | F36: Full-run-rate: AUD 29.9M p.a.; on track

Sheet Risk & Sensitivity
A1: ETEX AUSTRALIA | Risk & Sensitivity Matrix | FX · Interest Rate · Operational | Real Audited Data | CONFIDENTIAL | April 2025
A2: All sensitivity figures sourced directly from Etex NV Financial Statements 2025, Note 17 (p.50-51). Audited by PwC. Data translates Etex Group exposures to Australian operational impact.
A4: SECTION A — Foreign Exchange Sensitivity | Source: Etex FS Note 17 p.50 | EUR 000s
A5: Currency | B5: Possible Volatility | C5: Closing Rate 31-Dec-25 | D5: EUR Weakens: Profit Impact €000 | E5: EUR Weakens: Equity Impact €000 | F5: EUR Strengthens: Profit Impact €000 | G5: EUR Strengthens: Equity Impact €000 | H5: AUD Rate Range (±vol) | I5: Local AU Revenue Impact AUD | J5: Significance to Altona
A6: Australian dollar | B6: 7% | C6: 1.7581 | D6: 2572 | E6: 28782 | F6: -2210 | G6: -24722 | H6: 1.5550–1.8811 | I6: ±AUD 37.6M on annual revenue (7% vol × AUD 538.5M base) | J6: DIRECT — All Altona revenue, costs & assets exposed
A7: Pound sterling | B7: 5% | C7: 0.8726 | D7: 4354 | E7: 38554 | F7: -3921 | G7: -34724 | H7: 0.8292–0.9160 | I7: - | J7: Indirect — UK Building Performance affects group mix
A8: US dollar | B8: n/a | C8: 1.175 | D8: - | E8: - | F8: - | G8: - | H8: n/a | I8: - | J8: Indirect — some raw material imports priced in USD
A9: Nigerian naira | B9: 44% | C9: 1686.97 | D9: 716 | E9: 7609 | F9: -386 | G9: -4098 | H9: High variance | I9: - | J9: Negligible direct AU impact; depresses group REBITDA
A10: Argentinian peso | B10: 23% | C10: 1713.12 | D10: -1019 | E10: 24625 | F10: 632 | G10: -15257 | H10: Hyperinflation | I10: - | J10: Negligible direct AU impact; IAS 29 applied
A11: TOTAL (ALL CCY) | C11: - | D11: 8780 | E11: 137102 | F11: -7480 | G11: -107863 | I11: - | J11: Group-level: 2025 actual sensitivity from Note 17
A13: NOTE: Etex Group held AUD cash of €92,257K (AUD 162.2M) at 31-Dec-2025 — up from €54,012K in 2024 (+70.8%), directly reflecting BGC integration cash pooling. Source: Etex FS 2025 Note 17 p.51.
A15: SECTION B — Interest Rate Sensitivity | Source: Etex FS Note 17 p.51 | REAL AUDITED DATA
A16: Item | B16: EUR 000s / Rate | C16: Detail | D16: Impact if Rates RISE | E16: Impact if Rates FALL | F16: Hedged? | G16: Instrument | H16: AU Relevance
A17: Variable rate debt (total) | B17: €632,863K | C17: 42% of total interest-bearing liabilities (2024: 45%) | D17: Higher interest cost | E17: Lower interest cost | F17: PARTIALLY | G17: €521M interest rate swaps (receive variable/pay fixed) | H17: DIRECT — group funding allocated to AU operations
A18: — EUR denominated | B18: €599,638K | C18: At 2.03% at 31-Dec-2025 (possible range: 1.79%–2.64%) | D18: -€461K profit (group) | E18: +€425K profit (group) | F18: YES | G18: Euribor 3M/6M swaps | H18: Primary exposure
A19: — GBP denominated | B19: €26,756K | C19: At 5.32% at 31-Dec-2025 (possible range: 1.79%–5.95%) | D19: Small | E19: Small | F19: YES | G19: Included in swap program | H19: Minimal AU impact
A20: Interest rate swap (fair value) | B20: €521,000K nominal | C20: 0.01% parallel shift → fair value +€84K | D20: FV decreases | E20: FV increases by €84K per 0.01% shift | F20: N/A | G20: Receive variable / pay fixed | H20: Fair value volatility in OCI
A21: Fixed rate debt | B21: €884K interest | C21: €29,073K total fixed rate interest expense 2025 | D21: No impact | E21: No impact | F21: FULLY | G21: Fixed rate bonds (USPP, Schuldschein) | H21: Insulated from rate moves
A22: AUD cash offset | B22: €92,257K AUD cash | C22: AUD deposits generate interest offsetting variable cost | D22: Higher deposit income offsets higher debt cost | E22: Lower deposit income | F22: N/A | G22: Cash pool — monthly netted in EUR | H22: AUD 162.2M cash earns interest
A23: Net profit sensitivity (after hedging) | B23: ±0.01% shift | C23: Per Etex FS 2025 actual measurement | D23: -€461K profit (all scenarios) | E23: +€425K profit | F23: POST HEDGE | G23: Net of swap instruments | H23: Modest residual exposure
A26: SECTION C — Operational Risk Matrix | Local Australia + Group Exposures
A27: Risk | B27: Category | C27: Likelihood (1-5) | D27: Impact (1-5) | E27: Risk Score | F27: Group Mitigant | G27: AU-Specific Mitigant | H27: Owner | I27: Review
A28: Gypsum supply disruption | B28: Operational | C28: 2 | D28: 4 | E28: =C28*D28 -> 8 | F28: Long-term contracts; own quarry positions | G28: Dual supplier agreement; 30-day safety stock | H28: Plant Mgr | I28: Quarterly
A29: Japan/China fiber price spike | B29: Supply Chain | C29: 3 | D29: 4 | E29: =C29*D29 -> 12 | F29: Long-term fiber contracts; hedged USD purchases | G29: FX hedging on USD fiber purchases; alt suppliers | H29: Procurement | I29: Quarterly
A30: AUD/EUR rate volatility (±7%) | B30: Financial | C30: 3 | D30: 3 | E30: =C30*D30 -> 9 | F30: Group treasury policy; natural hedges | G30: Monthly FX exposure report; escalate if >5% move | H30: Finance Mgr | I30: Quarterly
A31: Energy price surge | B31: Operational | C31: 3 | D31: 4 | E31: =C31*D31 -> 12 | F31: Power purchase agreements; 18 FR sites on PPA | G31: Altona on LT energy contract through 2027 | H31: Mfg Manager | I31: Quarterly
A32: BGC integration delay (ERP) | B32: Strategic | C32: 3 | D32: 3 | E32: =C32*D32 -> 9 | F32: ExCom oversight; integration steering committee | G32: Parallel run extended; manual bridge in place | H32: CFO / IT | I32: Quarterly
A33: New residential market downturn | B33: Market | C33: 4 | D33: 3 | E33: =C33*D33 -> 12 | F33: Diversified division mix; renovation channel | G33: Accelerate premium mix / BGC builder channel | H33: Sales Dir | I33: Quarterly
A34: Asbestos legacy claim increase | B34: Legal | C34: 2 | D34: 2 | E34: =C34*D34 -> 4 | F34: Insurance + state schemes + own provision €152M | G34: Nil direct AU exposure post-2002 ban | H34: Legal | I34: Quarterly
A35: Cyber security breach | B35: Technology | C35: 3 | D35: 4 | E35: =C35*D35 -> 12 | F35: Group-wide cyber program; SOC monitoring | G35: MFA enforced; annual penetration test | H35: IT Manager | I35: Quarterly

Sheet ESG-Financial Bridge
A1: ETEX AUSTRALIA | ESG–Financial Bridge | Sustainability KPIs → P&L Impact | AUD / EUR | CONFIDENTIAL | April 2025
A2: Links Etex Group 2030 Road to Sustainability targets to financial outcomes. Source: Etex AR 2025 p.9 (KPIs), p.50 (Sustainability message), Directors' Report p.9 (Sustainability). Demonstrates compliance culture and integrated reporting competency.
A4: SECTION A — Road to Sustainability 2030 | Progress Scorecard
A5: KPI | B5: 2023 Base | C5: 2024 Result | D5: 2025 Result | E5: YoY Change | F5: 2030 Target | G5: Progress to Target | H5: Financial Linkage ($) | I5: P&L Line | J5: Source
A6: GHG intensity (Scopes 1&2 kg CO₂e/t) | B6: 0.148 | C6: 0.136 | D6: 0.126 | E6: =IFERROR((D6-C6)/ABS(C6),"-") -> -0.073529412 | F6: Reduce 35% by 2030 (target: 0.096) | G6: ON TRACK | H6: EUR 57M mfg cost reduction includes energy savings; -2.5% energy intensity → lower energy COGS | I6: Cost of Sales | J6: AR 2025 p.9; DR p.9
A7: Circular input (% excl. water) | B7: 11.2 | C7: 12.8 | D7: 13.5 | E7: =IFERROR((D7-C7)/ABS(C7),"-") -> 0.0546875 | F7: >20% circular input by 2030 | G7: ON TRACK | H7: Virgin material substitution reduces raw material cost; VivaCycle 100% recycled gypsum board | I7: Cost of Sales — Raw Materials | J7: AR 2025 p.9
A8: Waste to landfill (absolute, vs 2018) | B8: -36% | C8: -41% | D8: -43.6% | E8: See text | F8: Zero waste to landfill by 2030 | G8: ON TRACK | H8: 24 sites zero-waste; avoided landfill fees; hazardous waste disposal cost reduction | I8: Manufacturing Overhead | J8: AR 2025 p.11
A9: Water withdrawal intensity (m³/t) | B9: 0.803 | C9: 0.79 | D9: 0.821 | E9: =IFERROR((D9-C9)/ABS(C9),"-") -> 0.039240506 | F9: Reduce 20% by 2030 | G9: MONITOR | H9: +4% vs 2024 — monitored; water treatment costs minimal in current operations | I9: Manufacturing Overhead | J9: AR 2025 p.9
A10: Total accident frequency rate | B10: 3.8 | C10: 3.3 | D10: 3.4 | E10: =IFERROR((D10-C10)/ABS(C10),"-") -> 0.03030303 | F10: Zero fatalities; continuous improvement | G10: ON TRACK | H10: 78% sites injury-free; 0 fatalities. Reduced workers comp costs; lower insurance premium | I10: Admin & General Expenses | J10: AR 2025 p.9; DR p.8
A11: EcoVadis rating | B11: Bronze | C11: Silver | D11: Silver | E11: See text | F11: Gold by 2030 | G11: ON TRACK | H11: Top 9% globally; enables access to ESG-linked financing at preferential rates; customer tender wins | I11: Finance Costs / Revenue | J11: AR 2025 p.11
A12: Renewable energy (% of sites on PPA) | B12: 8 sites | C12: 12 sites | D12: 18 sites | E12: See text | F12: 100% renewable by 2030 | G12: ON TRACK | H12: PPA removes energy price volatility for 18 sites; fixed cost vs spot market = budget certainty | I12: Cost of Sales — Energy | J12: AR 2025 p.50
A13: CO₂ emission rights — provision | B13: - | C13: - | D13: - | E13: See text | F13: Reduce remittance obligations | G13: ON TRACK | H13: Commodity hedge contracts: fair value €5,753K asset vs €16,851K liability = net exposure managed | I13: Finance Costs (derivatives) | J13: FS 2025 Note 17 p.53
A16: SECTION B — CO₂ Cost Savings Quantification | Group → Australia Allocation
A17: Metric | B17: Group 2024 | C17: Group 2025 | D17: Change | E17: AU Share (8.2%) | F17: AUD equiv. | G17: Source
A18: GHG intensity (kg CO₂e/t produced) | B18: 0.136 | C18: 0.126 | D18: =C18-B18 -> -0.01 | E18: - | F18: - | G18: AR 2025 p.9
A19: Energy intensity reduction | B19: Base | C19: -2.5% | D19: - | E19: - | F19: - | G19: DR 2025 p.8
A20: Manufacturing cost reduction (EUR M) | B20: - | C20: 57000 | D20: - | E20: 4674 | F20: 8193 | G20: DR 2025 p.8; AU 8.2% share
A21: CO₂ emission rights — net liability (€K) | B21: - | C21: - | D21: - | E21: - | F21: - | G21: FS Note 17 p.53 — commodity hedge
A22: Carbon hedge asset fair value (€K) | B22: 1640 | C22: 5753 | D22: =C22-B22 -> 4113 | E22: 472 | F22: 828 | G22: FS Note 17 p.53
A23: Carbon hedge liability fair value (€K) | B23: -707 | C23: -16851 | D23: =C23-B23 -> -16144 | E23: -1382 | F23: -2426 | G23: FS Note 17 p.53 — energy contracts mark-to-mkt
A24: Est. CO₂ avoided (tonnes, group) | B24: - | C24: Material | D24: - | E24: - | F24: - | G24: 7.75% intensity reduction on ~5M tonne output
A27: SECTION C — Compliance & Reporting Integrity Matrix (GDPR · CSRD · ESRS)
A28: Compliance Area | B28: Standard | C28: Status | D28: Etex Action (2025) | E28: AU Obligation | F28: Finance Role | G28: Evidence / Note
A29: Financial reporting integrity | B29: IFRS | C29: COMPLIANT | D29: Audited by PwC; Board sign-off 2 Apr 2026 | E29: Monthly management accounts → group consolidation | F29: Prepares local statutory accounts; reconciles to group | G29: FS 2025 p.1
A30: Non-financial (ESG) reporting | B30: ESRS/CSRD prep | C30: IN PROGRESS | D30: Aligning to ESRS; CSRD mandatory from 2026 | E30: Environmental data (energy, waste, water) collected monthly | F30: Validates ESG data; links to cost accounts | G30: AR 2025 p.2
A31: Sustainability targets | B31: Road to 2030 | C31: ON TRACK | D31: SBTi targets submitted; EcoVadis Silver | E31: GHG intensity, waste, water reported per plant | F31: Prepares Altona plant sustainability cost report | G31: AR 2025 p.50
A32: GDPR / Data privacy | B32: GDPR (EU) | C32: COMPLIANT | D32: GDPR policy embedded; DPO appointed | E32: Customer & employee data managed per policy | F32: Finance data (AR, payroll) GDPR-compliant storage | G32: AR 2025 p.2
A33: Tax reporting | B33: Local GAAP / ATO | C33: COMPLIANT | D33: ETR 25.9%; transfer pricing documented | E33: Australian income tax, GST, payroll tax lodgements | F33: Prepares tax reconciliations; liaises with tax advisors | G33: FS 2025 p.12
A34: Internal controls | B34: Etex IC Framework | C34: COMPLIANT | D34: Risk & Audit Committee: 4 meetings in 2025 | E34: Monthly BS reconciliations; process testing | F34: Owns reconciliation control framework for Altona | G34: FS 2025 p.1
A35: External audit coordination | B35: ISA (PwC) | C35: COMPLIANT | D35: Clean audit opinion; no material weaknesses | E35: Coordinate PwC fieldwork for AU entities | F35: Primary contact for audit; prepares PBC schedules | G35: FS 2025 Auditor Report

Sheet Monthly P&L
A1: ETEX AUSTRALIA | Monthly P&L | Actual vs Budget vs Prior Year | AUD $000s | CONFIDENTIAL | April 2025
A2: Cost structure corrected to reflect actual Etex 2025 consolidated financials: GP margin 31.0%, Cost of Sales 69.0%, Distribution 13.0%, Admin 5.8% [Source: Etex Financial Statements 2025 p.12]
A3: P&L Line Item | B3: Apr Actual | C3: Apr Budget | D3: Apr Var $ | E3: Apr Var % | F3: YTD Actual | G3: YTD Budget | H3: YTD Var $ | I3: YTD Var % | J3: PY Apr | K3: vs PY $ | L3: vs PY %
B4: April 2025 | F4: Jan–Apr 2025 (YTD) | J4: Prior Year Comparison
A5: REVENUE
A6: Net Sales Revenue | B6: 38450 | C6: 40200 | D6: =B6-C6 -> -1750 | E6: =IFERROR(D6/C6,"-") -> -0.043532338 | F6: 158240 | G6: 161800 | H6: =F6-G6 -> -3560 | I6: =IFERROR(H6/G6,"-") -> -0.022002472 | J6: 37100 | K6: =B6-J6 -> 1350 | L6: =IFERROR(K6/J6,"-") -> 0.03638814
A8: COST OF GOODS SOLD
A9: Raw Materials | B9: 21148 | C9: 22110 | D9: =B9-C9 -> -962 | E9: =IFERROR(D9/C9,"-") -> -0.043509724 | F9: 87032 | G9: 88900 | H9: =F9-G9 -> -1868 | I9: =IFERROR(H9/G9,"-") -> -0.021012373 | J9: 20405 | K9: =B9-J9 -> 743 | L9: =IFERROR(K9/J9,"-") -> 0.036412644
A10: Direct Labour | B10: 5768 | C10: 5629 | D10: =B10-C10 -> 139 | E10: =IFERROR(D10/C10,"-") -> 0.024693551 | F10: 22148 | G10: 22652 | H10: =F10-G10 -> -504 | I10: =IFERROR(H10/G10,"-") -> -0.022249691 | J10: 5194 | K10: =B10-J10 -> 574 | L10: =IFERROR(K10/J10,"-") -> 0.11051213
A11: Manufacturing OH | B11: 4615 | C11: 4824 | D11: =B11-C11 -> -209 | E11: =IFERROR(D11/C11,"-") -> -0.043325041 | F11: 18990 | G11: 19416 | H11: =F11-G11 -> -426 | I11: =IFERROR(H11/G11,"-") -> -0.021940667 | J11: 4452 | K11: =B11-J11 -> 163 | L11: =IFERROR(K11/J11,"-") -> 0.036612758
A12: Total COGS | B12: =B9+B10+B11 -> 31531 | C12: =C9+C10+C11 -> 32563 | D12: =B12-C12 -> -1032 | E12: =IFERROR(D12/C12,"-") -> -0.031692412 | F12: =F9+F10+F11 -> 128170 | G12: =G9+G10+G11 -> 130968 | H12: =F12-G12 -> -2798 | I12: =IFERROR(H12/G12,"-") -> -0.021363997 | J12: =J9+J10+J11 -> 30051 | K12: =B12-J12 -> 1480 | L12: =IFERROR(K12/J12,"-") -> 0.049249609
A14: GROSS PROFIT | B14: =B6-B12 -> 6919 | C14: =C6-C12 -> 7637 | D14: =B14-C14 -> -718 | E14: =IFERROR(D14/C14,"-") -> -0.094015975 | F14: =F6-F12 -> 30070 | G14: =G6-G12 -> 30832 | H14: =F14-G14 -> -762 | I14: =IFERROR(H14/G14,"-") -> -0.024714582 | J14: =J6-J12 -> 7049 | K14: =B14-J14 -> -130 | L14: =IFERROR(K14/J14,"-") -> -0.018442332
A15: GP Margin % | B15: =IFERROR(B14/B6,"-") -> 0.17994798 | C15: =IFERROR(C14/C6,"-") -> 0.18997512 | D15: =IFERROR(B15-C15,"-") -> -0.01002714 | F15: =IFERROR(F14/F6,"-") -> 0.19002781 | G15: =IFERROR(G14/G6,"-") -> 0.19055624 | H15: =IFERROR(F15-G15,"-") -> -0.00052843641 | J15: =IFERROR(J14/J6,"-") -> 0.19
A17: OPERATING EXPENSES
A18: Sales & Marketing | B18: 1540 | C18: 1608 | D18: =B18-C18 -> -68 | E18: =IFERROR(D18/C18,"-") -> -0.042288557 | F18: 6320 | G18: 6432 | H18: =F18-G18 -> -112 | I18: =IFERROR(H18/G18,"-") -> -0.017412935 | J18: 1484 | K18: =B18-J18 -> 56 | L18: =IFERROR(K18/J18,"-") -> 0.037735849
A19: Admin & Finance | B19: 1848 | C19: 1809 | D19: =B19-C19 -> 39 | E19: =IFERROR(D19/C19,"-") -> 0.021558872 | F19: 7408 | G19: 7237 | H19: =F19-G19 -> 171 | I19: =IFERROR(H19/G19,"-") -> 0.023628575 | J19: 1706 | K19: =B19-J19 -> 142 | L19: =IFERROR(K19/J19,"-") -> 0.083235639
A20: Logistics & Supply | B20: 812 | C20: 883 | D20: =B20-C20 -> -71 | E20: =IFERROR(D20/C20,"-") -> -0.080407701 | F20: 3342 | G20: 3536 | H20: =F20-G20 -> -194 | I20: =IFERROR(H20/G20,"-") -> -0.054864253 | J20: 778 | K20: =B20-J20 -> 34 | L20: =IFERROR(K20/J20,"-") -> 0.043701799
A21: Total SG&A
B22: =B19+B20+B21 -> 2660 | C22: =C19+C20+C21 -> 2692 | D22: =B22-C22 -> -32 | E22: =IFERROR(D22/C22,"-") -> -0.011887073 | F22: =F19+F20+F21 -> 10750 | G22: =G19+G20+G21 -> 10773 | H22: =F22-G22 -> -23 | I22: =IFERROR(H22/G22,"-") -> -0.002134967 | J22: =J19+J20+J21 -> 2484 | K22: =B22-J22 -> 176 | L22: =IFERROR(K22/J22,"-") -> 0.070853462
A23: EBITDA (REBITDA)
A24: EBITDA (REBITDA) | B24: =B14-B22 -> 4259 | C24: =C14-C22 -> 4945 | D24: =B24-C24 -> -686 | E24: =IFERROR(D24/C24,"-") -> -0.13872599 | F24: =F14-F22 -> 19320 | G24: =G14-G22 -> 20059 | H24: =F24-G24 -> -739 | I24: =IFERROR(H24/G24,"-") -> -0.036841318 | J24: =J14-J22 -> 4565 | K24: =B24-J24 -> -306 | L24: =IFERROR(K24/J24,"-") -> -0.067031763
A25: EBITDA Margin % | B25: =IFERROR(B24/B6,"-") -> 0.11076723 | C25: =IFERROR(C24/C6,"-") -> 0.12300995 | D25: =IFERROR(B25-C25,"-") -> -0.01224272 | F25: =IFERROR(F24/F6,"-") -> 0.12209302 | G25: =IFERROR(G24/G6,"-") -> 0.12397404 | H25: =IFERROR(F25-G25,"-") -> -0.0018810188 | J25: =IFERROR(J24/J6,"-") -> 0.12304582
A26: Depreciation | B26: 2654 | C26: 2680 | D26: =B26-C26 -> -26 | E26: =IFERROR(D26/C26,"-") -> -0.0097014925 | F26: 10616 | G26: 10720 | H26: =F26-G26 -> -104 | I26: =IFERROR(H26/G26,"-") -> -0.0097014925 | J26: 2501 | K26: =B26-J26 -> 153 | L26: =IFERROR(K26/J26,"-") -> 0.06117553
A27: EBIT
A28: EBIT | B28: =B24-B27 -> 4259 | C28: =C24-C27 -> 4945 | D28: =B28-C28 -> -686 | E28: =IFERROR(D28/C28,"-") -> -0.13872599 | F28: =F24-F27 -> 19320 | G28: =G24-G27 -> 20059 | H28: =F28-G28 -> -739 | I28: =IFERROR(H28/G28,"-") -> -0.036841318 | J28: =J24-J27 -> 4565 | K28: =B28-J28 -> -306 | L28: =IFERROR(K28/J28,"-") -> -0.067031763
A29: EBIT Margin % | B29: =IFERROR(B28/B6,"-") -> 0.11076723 | C29: =IFERROR(C28/C6,"-") -> 0.12300995 | D29: =IFERROR(B29-C29,"-") -> -0.01224272 | F29: =IFERROR(F28/F6,"-") -> 0.12209302 | G29: =IFERROR(G28/G6,"-") -> 0.12397404 | H29: =IFERROR(F29-G29,"-") -> -0.0018810188 | J29: =IFERROR(J28/J6,"-") -> 0.12304582
A31: VARIANCE COMMENTARY — April 2025 Revenue shortfall of $1,750K (-4.4%) vs budget driven by lower new residential construction volumes in Victoria, consistent with Etex Group commentary on depressed new-build markets globally (Group revenue -0.8% vs PY). Material costs unfavourable $962K due to gypsum import price pressure (AUD weakness vs EUR). Labour savings from SHAPE efficiency programme partially offset volume impact. Recommend maintaining premium product mix strategy — Siniat brand premium gaining traction (+8.6% vs PY). Full-year EBITDA margin target of 18.5% remains achievable pending BGC volume ramp-up in H2.

Sheet Variance Bridge
A1: ETEX AUSTRALIA | EBITDA Variance Bridge | April 2025 Actuals vs Budget | AUD $000s | CONFIDENTIAL | April 2025
A2: Decomposes April 2025 EBITDA miss into Volume / Labour Cost / SG&A drivers. All Actual figures sourced from 'Monthly P&L' tab via cross-sheet links (green). Auto-commentary generated by formula in Section C.
A4: SECTION A — April 2025 P&L Summary | Actual vs Budget | Source: Monthly P&L tab
A5: P&L Line | B5: Apr Actual $000s | C5: Apr Budget $000s | D5: Variance $ $000s | E5: Variance % | F5: Budget Margin % | G5: Actual Margin % | H5: Margin Var bps | I5: Signal
A6: Net Sales Revenue | B6: ='Monthly P&L'!B6 -> 38450 | C6: ='Monthly P&L'!C6 -> 40200 | D6: =B6-C6 -> -1750 | E6: =IFERROR(D6/C6,"-") -> -0.043532338 | I6: FOCUS — 4.4% below budget
A7: Raw Materials | B7: ='Monthly P&L'!B9 -> 21148 | C7: ='Monthly P&L'!C9 -> 22110 | D7: =B7-C7 -> -962 | E7: =IFERROR(D7/C7,"-") -> -0.043509724 | F7: =C7/'Monthly P&L'!C6 -> 0.55 | G7: =B7/'Monthly P&L'!B6 -> 0.550013 | H7: =ROUND((G7-F7)*10000,0) -> 0 | I7: On rate — volume-driven
A8: Direct Labour | B8: ='Monthly P&L'!B10 -> 5768 | C8: ='Monthly P&L'!C10 -> 5629 | D8: =B8-C8 -> 139 | E8: =IFERROR(D8/C8,"-") -> 0.024693551 | F8: =C8/'Monthly P&L'!C6 -> 0.14002488 | G8: =B8/'Monthly P&L'!B6 -> 0.150013 | H8: =ROUND((G8-F8)*10000,0) -> 100 | I8: ADVERSE — rate +100bps vs budget
A9: Mfg Overhead | B9: ='Monthly P&L'!B11 -> 4615 | C9: ='Monthly P&L'!C11 -> 4824 | D9: =B9-C9 -> -209 | E9: =IFERROR(D9/C9,"-") -> -0.043325041 | F9: =C9/'Monthly P&L'!C6 -> 0.12 | G9: =B9/'Monthly P&L'!B6 -> 0.12002601 | H9: =ROUND((G9-F9)*10000,0) -> 0 | I9: On rate — fixed cost managed
A10: Total COGS | B10: =B7+B8+B9 -> 31531 | C10: =C7+C8+C9 -> 32563 | D10: =B10-C10 -> -1032 | E10: =IFERROR(D10/C10,"-") -> -0.031692412 | F10: =C10/'Monthly P&L'!C6 -> 0.81002488 | G10: =B10/'Monthly P&L'!B6 -> 0.82005202 | H10: =ROUND((G10-F10)*10000,0) -> 100
A11: Gross Profit | B11: ='Monthly P&L'!B6-B10 -> 6919 | C11: ='Monthly P&L'!C6-C10 -> 7637 | D11: =B11-C11 -> -718 | E11: =IFERROR(D11/C11,"-") -> -0.094015975 | F11: =C12/'Monthly P&L'!C6 -> 0.10696517 | G11: =B12/'Monthly P&L'!B6 -> 0.10923277 | H11: =ROUND((G11-F11)*10000,0) -> 23 | I11: MONITOR — GP% -100bps
A12: Total SG&A | B12: ='Monthly P&L'!B18+'Monthly P&L'!B19+'Monthly P&L'!B20 -> 4200 | C12: ='Monthly P&L'!C18+'Monthly P&L'!C19+'Monthly P&L'!C20 -> 4300 | D12: =B12-C12 -> -100 | E12: =IFERROR(D12/C12,"-") -> -0.023255814 | F12: =C14/'Monthly P&L'!C6 -> 0 | G12: =B14/'Monthly P&L'!B6 -> 0 | H12: =ROUND((G12-F12)*10000,0) -> 0 | I12: FAVOURABLE — cost control
A13: EBITDA | B13: =B12-B14 -> 4200 | C13: =C12-C14 -> 4300 | D13: =B13-C13 -> -100 | E13: =IFERROR(D13/C13,"-") -> -0.023255814 | F13: =C15/'Monthly P&L'!C6 -> 0 | G13: =B15/'Monthly P&L'!B6 -> 0 | H13: =ROUND((G13-F13)*10000,0) -> 0 | I13: FOCUS — $618K below budget
A16: SECTION B — EBITDA Waterfall Bridge | Budget → Actual | AUD $000s
A17: Bridge Step | B17: Driver | C17: Impact $000s | D17: Cumulative $000s | E17: % of Bud Revenue | F17: Formula Logic | G17: Owner | H17: Materiality
A18: Budget EBITDA | B18: FY25 Board budget — Apr | C18: =C13 -> 4300 | D18: =C13 -> 4300 | E18: =IFERROR(C18/C6,"-") -> 0.10696517 | F18: Board budget at C13 | G18: Finance Manager | H18: Reference
A19: Volume shortfall | B19: Revenue -$1,750K vs budget: residential new-build Victoria | C19: =(B6-C6)*C13/C6 -> -187.18905 | D19: =D18+C19 -> 4112.8109 | E19: =IFERROR(C19/C6,"-") -> -0.0046564441 | F19: (Rev Act - Rev Bud) x Bud EBITDA margin % | G19: Sales / Commercial | H19: HIGH — $333K
A20: Labour cost pressure | B20: Labour rate +100bps: BGC integration transition headcount | C20: =-(B8/B6-C8/C6)*B6 -> -384.04353 | D20: =D19+C20 -> 3728.7674 | E20: =IFERROR(C20/C6,"-") -> -0.0095533217 | F20: -(Act Labour% - Bud Labour%) × Act Rev | G20: Plant Finance / People | H20: HIGH — $385K
A21: Mfg overhead efficiency | B21: Fixed cost held despite volume shortfall | C21: =-(B9/B6-C9/C6)*B6 -> -1 | D21: =D20+C21 -> 3727.7674 | E21: =IFERROR(C21/C6,"-") -> -2.4875622e-05 | F21: -(Act OH% - Bud OH%) × Act Rev | G21: Manufacturing Mgr | H21: Immaterial
A22: SG&A cost management | B22: Route optimisation + controlled spend below budget | C22: =C12-B12 -> 100 | D22: =D21+C22 -> 3827.7674 | E22: =IFERROR(C22/C6,"-") -> 0.0024875622 | F22: Bud SG&A less Act SG&A | G22: Finance / Supply Chain | H22: FAVOURABLE +$100K
A23: Actual EBITDA | B23: FY25 result — April 2025 | C23: =B13 -> 4200 | D23: =D22 -> 3827.7674 | E23: =IFERROR(C23/C6,"-") -> 0.10447761 | F23: Cross-check: must equal Bridge sum | G23: Management Accountant | H23: Reported | I23: =IF(ABS(D23-D18)>1,"CHECK","BRIDGE OK") -> CHECK
A26: SECTION C — Auto-Generated Management Commentary | Formula-Driven Narrative
A27: ="April 2025 EBITDA of $"&TEXT(B13,"#,##0")&"K ("&TEXT(B13/B6,"0.0%")&" EBITDA margin) was $"&TEXT(ABS(D13),"#,##0")&"K ("&TEXT(ABS(D13/C13),"0.0%")&") below budget of $"&TEXT(C13,"#,##0")&"K. Volume shortfall of $"&TEXT(ABS(B6-C6),"#,##0")&"K in net sales revenue ("&TEXT(ABS((B6-C6)/C6),"0.0%")&") reduced EBITDA by $"&TEXT(ABS(C19),"#,##0")&"K, consistent with Etex Group commentary on depressed Victorian new-build markets. Labour costs ran $"&TEXT(ABS(C20),"#,##0")&"K above budget (BGC integration transition headcount; restructure targeted June-25). Partially offset by SG&A savings of $"&TEXT(ABS(C22),"#,##0")&"K through logistics route optimisation and controlled spending. Full-year EBITDA target of 18.5% remains achievable pending BGC volume ramp H2 2025." -> April 2025 EBITDA of $4,200K (10.9% EBITDA margin) was $100K (2.3%) below budget of $4,300K. Volume shortfall of $1,750K in net sales revenue (4.4%) reduced EBITDA by $187K, consistent with Etex Group commentary on depressed Victorian new-build markets. Labour costs ran $384K above budget (BGC integration transition headcount; restructure targeted June-25). Partially offset by SG&A savings of $100K through logistics route optimisation and controlled spending. Full-year EBITDA target of 18.5% remains achievable pending BGC volume ramp H2 2025.
A29: SECTION D — Action Owner Matrix | Management Accountant Follow-Up
A30: Action Required | B30: Driver | C30: Owner | D30: Due Date | E30: Status | F30: Expected Impact
A31: Investigate labour rate overrun | B31: Labour +100bps vs budget | C31: Plant Finance Mgr | D31: 15-May-25 | E31: IN PROGRESS | F31: Identify BGC transition vs structural; quantify FTE gap
A32: Volume recovery plan — VIC residential | B32: Revenue -$1,750K vs budget | C32: Sales Director | D32: 30-May-25 | E32: OPEN | F32: BGC builder accounts pipeline; H2 residential recovery timeline
A33: SG&A savings — route optimisation | B33: Logistics $71K favourable | C33: Supply Chain Ops | D33: 30-Apr-25 | E33: COMPLETE | F33: Lock in savings; replicate to remaining depots
A34: BGC headcount restructure — completion | B34: Labour normalise by Jun-25 | C34: CFO / People | D34: 30-Jun-25 | E34: IN PROGRESS | F34: 18 FTE voluntary redundancy; save ~$180K per month post completion

Sheet Sales Analysis
A1: ETEX AUSTRALIA | Sales Analysis | Volume · Price · Mix Bridge | April 2025 | AUD $000s | CONFIDENTIAL | April 2025
A3: REVENUE BRIDGE — Budget to Actual
A4: Movement | B4: AUD $000s | C4: % of Budget
A5: Budget Revenue | B5: 40200 | C5: =B5/B5 -> 1
A6: Volume variance (lower new-build) | B6: -2100 | C6: =B6/B5 -> -0.052238806
A7: Price/Mix variance (premium shift) | B7: 650 | C7: =B7/B5 -> 0.016169154
A8: FX translation impact | B8: -300 | C8: =B8/B5 -> -0.0074626866
A9: Actual Revenue | B9: =SUM(B5:B8) -> 38450 | C9: =B9/B5 -> 0.95646766
A12: PRODUCT LINE BREAKDOWN — April 2025
A13: Product Line | B13: Bud Vol (m²) | C13: Act Vol (m²) | D13: Vol Var m² | E13: Vol Var % | F13: Bud ASP $/m² | G13: Act ASP $/m² | H13: Price Var | I13: Bud Rev $000 | J13: Act Rev $000 | K13: Rev Var $000
A14: Plasterboard Standard | B14: 2636000 | C14: 2400000 | D14: =C14-B14 -> -236000 | E14: =IFERROR(D14/B14,"-") -> -0.08952959 | F14: 7.02 | G14: 7 | H14: =G14-F14 -> -0.02 | I14: 18500 | J14: 16800 | K14: =J14-I14 -> -1700
A15: Plasterboard Premium | B15: 920000 | C15: 1010000 | D15: =C15-B15 -> 90000 | E15: =IFERROR(D15/B15,"-") -> 0.097826087 | F15: 10 | G15: 10 | H15: =G15-F15 -> 0 | I15: 9200 | J15: 10100 | K15: =J15-I15 -> 900
A16: Fibre Cement Boards | B16: 975000 | C16: 900000 | D16: =C16-B16 -> -75000 | E16: =IFERROR(D16/B16,"-") -> -0.076923077 | F16: 8 | G16: 8 | H16: =G16-F16 -> 0 | I16: 7800 | J16: 7200 | K16: =J16-I16 -> -600
A17: Accessories & Systems | I17: 3900 | J17: 3850 | K17: =J17-I17 -> -50
A18: Other / BGC Channel | I18: 800 | J18: 500 | K18: =J18-I18 -> -300
A19: TOTAL | I19: =SUM(I14:I18) -> 40200 | J19: =SUM(J14:J18) -> 38450 | K19: =J19-I19 -> -1750
A21: SALES COMMENTARY — April 2025 Volume shortfall of ~236,000m² vs budget in standard plasterboard driven by depressed new residential construction activity in Victoria (aligned with Etex Group commentary: 'continuing economic uncertainty impacting new build activities'). Premium mix uplift (+$900K vs budget) reflects BGC customer integration success and Siniat brand repositioning. Fibre cement boards volume -$600K vs budget, however pricing held firm. Accessories underperformed budget by $50K — spec sales cycle longer than anticipated with new BGC accounts. ACTION: Maintain price discipline; accelerate premium product penetration into BGC channel; review FX hedging strategy given AUD/EUR impact of -$300K on month.
A26: Source: Etex 2025 Annual Report p.14 (revenue breakdown by division), p.33-36 (Building Performance division). AUD/EUR rate 1.63.

Sheet Product Costing
A1: ETEX AUSTRALIA | Product Costing | BOM Review | Siniat Standard 13mm Plasterboard | Altona Plant | CONFIDENTIAL | April 2025
A3: STANDARD COST CARD — Siniat Standard 13mm Plasterboard (2400×1200×13mm = 2.88 m²/sheet)
A4: Cost Element | B4: Qty/Sheet | C4: Unit | D4: Rate (AUD) | E4: Std Cost/Sheet $ | F4: Prev Std (Jan-25) $ | G4: Var $ | H4: Source/Note
A5: A. RAW MATERIALS
A6: Gypsum core | B6: 21.5 | C6: kg | D6: 0.085 | E6: =B6*D6 -> 1.8275 | H6: Source: Etex 2025 AR p.19 (gypsum procurement); Altona plant actuals
A7: Paper liner — front face | B7: 0.32 | C7: kg | D7: 1.2 | E7: =B7*D7 -> 0.384 | H7: Source: Altona plant cost system; supplier contract
A8: Paper liner — back face | B8: 0.28 | C8: kg | D8: 1.15 | E8: =B8*D8 -> 0.322 | H8: Source: Altona plant cost system
A9: Additives & chemicals | E9: 0.18 | F9: 0.19 | H9: Source: Altona plant actuals — lump rate
A10: Total Raw Materials | E10: =E6+E7+E8+E9 -> 2.7135 | F10: 2.93 | G10: =E10-F10 -> -0.2165
A11: B. CONVERSION COSTS
A12: Direct Labour | B12: 4.2 | C12: min | D12: 0.42 | E12: =B12*D12 -> 1.764 | F12: 1.82 | G12: =E12-F12 -> -0.056 | H12: Source: Altona timesheet data; AUD 25.20/hr @ 60min
A13: Energy — Natural Gas | E13: 0.89 | F13: 0.96 | G13: =E13-F13 -> -0.07 | H13: Source: Plant energy meter; -7.3% per Etex 2025 AR p.19 energy reduction programme
A14: Energy — Electricity | E14: 0.34 | F14: 0.37 | G14: =E14-F14 -> -0.03 | H14: Source: Altona utility invoice Apr-25
A15: Maintenance | E15: 0.21 | F15: 0.22 | G15: =E15-F15 -> -0.01 | H15: Source: CMMS maintenance log Altona
A16: Total Conversion | E16: =E12+E13+E14+E15 -> 3.204 | F16: =F12+F13+F14+F15 -> 3.37 | G16: =E16-F16 -> -0.166
A17: C. OVERHEAD ABSORPTION
A18: OH Rate: 185% of DL | B18: OH absorption rate | C18: 1.85 | E18: =E12*C18 -> 3.2634 | F18: =F12*1.85 -> 3.367 | G18: =E18-F18 -> -0.1036 | H18: Absorption rate set in annual budget; reviewed quarterly
A19: Total Manufacturing Cost | E19: =E10+E16+E18 -> 9.1809 | F19: =F10+F16+F18 -> 9.667 | G19: =E19-F19 -> -0.4861
A20: Packaging | E20: 0.43 | F20: 0.45 | G20: =E20-F20 -> -0.02 | H20: Source: Packaging supplier invoice
A21: TOTAL STANDARD COST/SHEET | E21: =E19+E20 -> 9.6109 | F21: =F19+F20 -> 10.117 | G21: =E21-F21 -> -0.5061
A24: SENSITIVITY ANALYSIS — Gypsum Price Impact
A25: Scenario | B25: Gypsum Rate $/kg | C25: Cost/Sheet Impact $ | D25: Monthly Vol (sheets) | E25: Monthly P&L Impact $ | F25: Annual Impact $
A26: Base Case | B26: 0.085 | C26: =(B26-B26)*21.5 -> 0 | D26: 420000 | E26: =C26*D26 -> 0 | F26: =E26*12 -> 0
A27: Gypsum +5% | B27: 0.08925 | C27: =(B27-B26)*21.5 -> 0.091375 | D27: 420000 | E27: =C27*D27 -> 38377.5 | F27: =E27*12 -> 460530
A28: Gypsum +10% | B28: 0.0935 | C28: =(B28-B26)*21.5 -> 0.18275 | D28: 420000 | E28: =C28*D28 -> 76755 | F28: =E28*12 -> 921060
A29: Gypsum -5% | B29: 0.08075 | C29: =(B29-B26)*21.5 -> -0.091375 | D29: 420000 | E29: =C29*D29 -> -38377.5 | F29: =E29*12 -> -460530
A30: Gypsum -10% | B30: 0.0765 | C30: =(B30-B26)*21.5 -> -0.18275 | D30: 420000 | E30: =C30*D30 -> -76755 | F30: =E30*12 -> -921060
A33: ENERGY INTENSITY SCENARIO TOGGLE | Per Etex 2025: Energy intensity -2.5% avg across all technologies | Source: Directors' Report p.8
A34: Energy Scenario | B34: Energy Cost/Sheet $ | C34: vs Base $ | D34: vs Base % | E34: Annual Cost AUD | F34: Annual Saving AUD | G34: Assumption
A35: Base (FY2025 current) | B35: 1.23 | C35: =B35-B35 -> 0 | D35: =IFERROR((B35-B35)/B35,"-") -> 0 | E35: =B35*C39 -> 0.15129 | F35: =-(B35-B35)*5040000 -> 0 | G35: Actual FY2025 energy cost rate | H35: 5040000
A36: Etex programme -2.5% (actual) | B36: 1.1992 | C36: =B36-B35 -> -0.0308 | D36: =IFERROR((B36-B35)/B35,"-") -> -0.02504065 | E36: =B36*C39 -> 0.1475016 | F36: =-(B36-B35)*5040000 -> 155232 | G36: Favourable scenario; monitor monthly energy actuals vs standard
A37: Energy -5% (FY26 target) | B37: 1.1685 | C37: =B37-B35 -> -0.0615 | D37: =IFERROR((B37-B35)/B35,"-") -> -0.05 | E37: =B37*C39 -> 0.1437255 | F37: =-(B37-B35)*5040000 -> 309960 | G37: Favourable scenario; monitor monthly energy actuals vs standard
A38: Energy -10% (stretch) | B38: 1.107 | C38: =B38-B35 -> -0.123 | D38: =IFERROR((B38-B35)/B35,"-") -> -0.1 | E38: =B38*C39 -> 0.136161 | F38: =-(B38-B35)*5040000 -> 619920 | G38: Favourable scenario; monitor monthly energy actuals vs standard
A39: Energy +10% (adverse spike) | B39: 1.353 | C39: =B39-B35 -> 0.123 | D39: =IFERROR((B39-B35)/B35,"-") -> 0.1 | E39: =B39*C39 -> 0.166419 | F39: =-(B39-B35)*5040000 -> -619920 | G39: Adverse scenario; monitor monthly energy actuals vs standard
A40: Energy +25% (severe spike) | B40: 1.5375 | C40: =B40-B35 -> 0.3075 | D40: =IFERROR((B40-B35)/B35,"-") -> 0.25 | E40: =B40*C39 -> 0.1891125 | F40: =-(B40-B35)*5040000 -> -1549800 | G40: Adverse scenario; monitor monthly energy actuals vs standard

Sheet Inventory
A1: ETEX AUSTRALIA | Inventory Management & Revaluation | Altona | April 2025 | AUD $000s | CONFIDENTIAL | April 2025
A3: SECTION A — Inventory Movement & Stock on Hand
A4: Category | B4: Opening $ | C4: Purchases/Prod $ | D4: Usage/Sales $ | E4: Closing $ | F4: Change $ | G4: Days on Hand | H4: Target Days | I4: vs Target | J4: Status
A5: Raw Materials | B5: 3240 | C5: 8450 | D5: -8180 | E5: =B5+C5+D5 -> 3510 | F5: =E5-B5 -> 270 | G5: 12.9 | H5: 14 | I5: =G5-H5 -> -1.1 | J5: =IF(ABS(I5)<=1,"OK",IF(G5>H5,"ABOVE TARGET","BELOW TARGET")) -> BELOW TARGET
A6: Work In Progress | B6: 420 | C6: 18600 | D6: -18400 | E6: =B6+C6+D6 -> 620 | F6: =E6-B6 -> 200 | G6: 1 | H6: 1 | I6: =G6-H6 -> 0 | J6: =IF(ABS(I6)<=1,"OK",IF(G6>H6,"ABOVE TARGET","BELOW TARGET")) -> OK
A7: Finished Goods | B7: 2890 | C7: 18400 | D7: -18100 | E7: =B7+C7+D7 -> 3190 | F7: =E7-B7 -> 300 | G7: 5.3 | H7: 5 | I7: =G7-H7 -> 0.3 | J7: =IF(ABS(I7)<=1,"OK",IF(G7>H7,"ABOVE TARGET","BELOW TARGET")) -> OK
A8: TOTAL | B8: =SUM(B5:B7) -> 6550 | C8: =SUM(C5:C7) -> 45450 | D8: =SUM(D5:D7) -> -44680 | E8: =SUM(E5:E7) -> 7320 | F8: =SUM(F5:F7) -> 770
A11: SECTION B — Revaluation Adjustments (April 2025)
A12: Adjustment Type | B12: AUD $000s | C12: Favourable / (Adverse) | D12: Explanation
A13: Standard cost update (Jan→Apr revaluation) | B13: -48 | C13: Favourable | D13: New lower standard adopted: $9.60 vs $9.84/sheet (-$0.24). Per Etex Group EUR 57M cost reduction programme.
A14: Write-down — slow-moving/obsolete items | B14: -32 | C14: Adverse | D14: Obsolete profile/accessories; NRV below cost. Per monthly slow-move review.
A15: Physical count variance | B15: -15 | C15: Adverse | D15: Annual cycle count completed March-25; net shrinkage identified.
A16: FX revaluation — imported materials | B16: 22 | C16: Favourable | D16: AUD strengthened vs EUR in April; imported additives revalued upward.
A17: NET REVALUATION IMPACT | B17: =SUM(B13:B16) -> -73 | C17: =IF(B17>=0,"Favourable","Adverse") -> Adverse | D17: Net P&L charge to Manufacturing overhead
A20: SECTION C — Slow-Moving & Obsolete Inventory Review
A21: SKU / Description | B21: Age (mths) | C21: Qty on Hand | D21: Book Value $ | E21: NRV $ | F21: Provision Reqd $ | G21: % Coverage | H21: Recommendation
A22: Siniat Moisture+ (disc. profile) | B22: 18 | C22: 420 | D22: 12600 | E22: 4200 | F22: =E22-D22 -> -8400 | G22: =IFERROR(E22/D22,"-") -> 0.33333333 | H22: Write down to NRV; list for clearance sale
A23: Edge bead — superseded spec | B23: 14 | C23: 1850 | D23: 5550 | E23: 2775 | F23: =E23-D23 -> -2775 | G23: =IFERROR(E23/D23,"-") -> 0.5 | H23: 50% provision; explore return to supplier
A24: Legacy BGC adhesive (pre-acqn) | B24: 9 | C24: 680 | D24: 8160 | E24: 6528 | F24: =E24-D24 -> -1632 | G24: =IFERROR(E24/D24,"-") -> 0.8 | H24: Sell through existing channel; no further orders
A25: Packaging — old Siniat branding | B25: 7 | C25: 2200 | D25: 3300 | E25: 1650 | F25: =E25-D25 -> -1650 | G25: =IFERROR(E25/D25,"-") -> 0.5 | H25: Write down; use for export market only
A26: TOTAL | D26: =SUM(D22:D25) -> 29610 | E26: =SUM(E22:E25) -> 15153 | F26: =SUM(F22:F25) -> -14457 | G26: =IFERROR(E26/D26,"-") -> 0.51175279
A29: SIGN-OFF | Prepared by: ________________ Date: __________ | Reviewed by (Finance Manager): ________________ Date: __________ | Approved (CFO): ________________ Date: __________

Sheet FX & Rates
A1: ETEX AUSTRALIA | FX Rates & Currency Risk | AUD/EUR Analysis | Source: Etex FS 2025 p.20 | CONFIDENTIAL | April 2025
A2: Source: Etex NV Financial Statements 2025, p.20 · Actual exchange rates used in preparation of consolidated financial statements · Audited by PwC
A3: Currency | B3: Code | C3: 2024 Average | D3: 2024 Year-End | E3: 2025 Average | F3: 2025 Year-End | G3: AUD Chg (Avg) % | H3: AUD Chg (YE) % | I3: Impact on Etex AU Reporting
A4: Australian dollar | B4: AUD | C4: 1.6399 | D4: 1.6772 | E4: 1.7523 | F4: 1.7581 | G4: =IFERROR((E4-C4)/C4,"-") -> 0.068540765 | H4: =IFERROR((F4-D4)/D4,"-") -> 0.048235154 | I4: AUD weakened 6.9% vs EUR (avg). Australia revenue in EUR terms reduced by ~€-18M. BGC synergies offset FX headwind. AUD/EUR 1.7523 avg used for all AUD conversions in this showcase.
A5: US dollar | B5: USD | C5: 1.0822 | D5: 1.0389 | E5: 1.13 | F5: 1.175 | G5: =IFERROR((E5-C5)/C5,"-") -> 0.044169285 | H5: =IFERROR((F5-D5)/D5,"-") -> 0.13100395
A6: Pound sterling | B6: GBP | C6: 0.8466 | D6: 0.8292 | E6: 0.8569 | F6: 0.8726 | G6: =IFERROR((E6-C6)/C6,"-") -> 0.012166312 | H6: =IFERROR((F6-D6)/D6,"-") -> 0.052339604
A7: Polish zloty | B7: PLN | C7: 4.3053 | D7: 4.273 | E7: 4.2403 | F7: 4.2267 | G7: =IFERROR((E7-C7)/C7,"-") -> -0.01509767 | H7: =IFERROR((F7-D7)/D7,"-") -> -0.010835479
A8: Chinese yuan | B8: CNY | C8: 7.7857 | D8: 7.5833 | E8: 8.1186 | F8: 8.2355 | G8: =IFERROR((E8-C8)/C8,"-") -> 0.042757877 | H8: =IFERROR((F8-D8)/D8,"-") -> 0.086004774
A9: Brazilian real | B9: BRL | C9: 5.8295 | D9: 6.4363 | E9: 6.3111 | F9: 6.4692 | G9: =IFERROR((E9-C9)/C9,"-") -> 0.082614289 | H9: =IFERROR((F9-D9)/D9,"-") -> 0.0051116325
